Workbook

Sheet 0. Dashboard
N1: lista_concelhos
B2: DASHBOARD INTERATIVO — NOVO HOSPITAL NO ALGARVE (MODELO 2) | N2: Albufeira
B3: Em que freguesia deveria ficar um novo hospital de 742 camas para minimizar o tempo de trajeto ponderado por população? — 67 freguesias candidatas do Algarve, capacidade real | N3: Alcoutim
N4: Aljezur
B5: ="🏆 MELHOR LOCALIZAÇÃO: "&UPPER('1. Resumo'!C9)&" (concelho de "&'1. Resumo'!C10&") — coordenadas: "&'1. Resumo'!C11 | N5: Castro Marim
N6: Faro
N7: Lagoa
B8: Nº FREGUESIAS | C8: POPULAÇÃO DO ALGARVE | D8: TEMPO MÉDIO ATUAL | E8: TEMPO MÉDIO C/ NOVO HOSP. | F8: REDUÇÃO DE TEMPO | G8: % CRÍTICAS (>60min) ATUAL | H8: % CRÍTICAS (>60min) ÓTIMO | I8: FREG. QUE USAM NOVO HOSP. | J8: DÉFICE DE CAMAS (ÓTIMO) | N8: Lagos
B9: ='1. Resumo'!C5 | C9: ='1. Resumo'!C6 | D9: ='1. Resumo'!C13 | E9: ='1. Resumo'!C14 | F9: ='1. Resumo'!C15 | G9: ='1. Resumo'!C17/100 | H9: ='1. Resumo'!C18/100 | I9: ='1. Resumo'!C20&" / "&'1. Resumo'!C5 | J9: ='1. Resumo'!C29 | N9: Loulé
N10: Monchique
N11: Olhão
B12: 🔎 FILTRO INTERATIVO — RESUMO POR CONCELHO SELECIONADO | N12: Portimão
D13: Nº Freguesias | E13: População total | F13: Tempo médio ATUAL (pond.) | G13: Tempo médio C/ NOVO HOSP. (pond.) | H13: Poupança média | I13: % que usa o novo hospital | N13: Silves
B14: Escolher Concelho: | C14: Portimão | D14: =COUNTIF('3. Impacto_Melhor_Local'!A3:A69,$C$14) | E14: =SUMIF('3. Impacto_Melhor_Local'!A3:A69,$C$14,'3. Impacto_Melhor_Local'!C3:C69) | F14: =SUMPRODUCT(('3. Impacto_Melhor_Local'!$A3:A69=$C$14)*'3. Impacto_Melhor_Local'!C3:C69*'3. Impacto_Melhor_Local'!E3:E69)/SUMPRODUCT(('3. Impacto_Melhor_Local'!$A3:A69=$C$14)*'3. Impacto_Melhor_Local'!C3:C69) | G14: =SUMPRODUCT(('3. Impacto_Melhor_Local'!$A3:A69=$C$14)*'3. Impacto_Melhor_Local'!C3:C69*'3. Impacto_Melhor_Local'!F3:F69)/SUMPRODUCT(('3. Impacto_Melhor_Local'!$A3:A69=$C$14)*'3. Impacto_Melhor_Local'!C3:C69) | H14: =SUMIF('3. Impacto_Melhor_Local'!A3:A69,$C$14,'3. Impacto_Melhor_Local'!G3:G69)/COUNTIF('3. Impacto_Melhor_Local'!A3:A69,$C$14) | I14: =COUNTIFS('3. Impacto_Melhor_Local'!A3:A69,$C$14,'3. Impacto_Melhor_Local'!I3:I69,"Sim")/COUNTIF('3. Impacto_Melhor_Local'!A3:A69,$C$14) | N14: São Brás de Alportel
N15: Tavira
N16: Vila Real de Santo António
B17: 📊 ANÁLISE POR CONCELHO | H17: 🏆 TOP 10 CANDIDATOS (menor custo = melhor) | N17: Vila do Bispo
B18: Concelho | C18: Nº Freguesias | D18: Tempo Médio ATUAL (min) | E18: Tempo Médio C/ NOVO HOSP. (min) | F18: % Usa Novo Hospital | H18: Freguesia (Concelho) | I18: Tempo Médio (min)
B19: Albufeira | C19: =COUNTIF('3. Impacto_Melhor_Local'!$A$3:$A$69,$B19) | D19: =IFERROR(ROUND(SUMPRODUCT(('3. Impacto_Melhor_Local'!$A$3:$A$69=$B19)*'3. Impacto_Melhor_Local'!$C$3:$C$69*'3. Impacto_Melhor_Local'!$E$3:$E$69)/SUMPRODUCT(('3. Impacto_Melhor_Local'!$A$3:$A$69=$B19)*'3. Impacto_Melhor_Local'!$C$3:$C$69),1),0) | E19: =IFERROR(ROUND(SUMPRODUCT(('3. Impacto_Melhor_Local'!$A$3:$A$69=$B19)*'3. Impacto_Melhor_Local'!$C$3:$C$69*'3. Impacto_Melhor_Local'!$F$3:$F$69)/SUMPRODUCT(('3. Impacto_Melhor_Local'!$A$3:$A$69=$B19)*'3. Impacto_Melhor_Local'!$C$3:$C$69),1),0) | F19: =COUNTIFS('3. Impacto_Melhor_Local'!$A$3:$A$69,$B19,'3. Impacto_Melhor_Local'!$I$3:$I$69,"Sim")/COUNTIF('3. Impacto_Melhor_Local'!$A$3:$A$69,$B19) | H19: ='2. Ranking_Candidatos'!C3&" ("&'2. Ranking_Candidatos'!B3&")" | I19: ='2. Ranking_Candidatos'!G3
B20: Alcoutim | C20: =COUNTIF('3. Impacto_Melhor_Local'!$A$3:$A$69,$B20) | D20: =IFERROR(ROUND(SUMPRODUCT(('3. Impacto_Melhor_Local'!$A$3:$A$69=$B20)*'3. Impacto_Melhor_Local'!$C$3:$C$69*'3. Impacto_Melhor_Local'!$E$3:$E$69)/SUMPRODUCT(('3. Impacto_Melhor_Local'!$A$3:$A$69=$B20)*'3. Impacto_Melhor_Local'!$C$3:$C$69),1),0) | E20: =IFERROR(ROUND(SUMPRODUCT(('3. Impacto_Melhor_Local'!$A$3:$A$69=$B20)*'3. Impacto_Melhor_Local'!$C$3:$C$69*'3. Impacto_Melhor_Local'!$F$3:$F$69)/SUMPRODUCT(('3. Impacto_Melhor_Local'!$A$3:$A$69=$B20)*'3. Impacto_Melhor_Local'!$C$3:$C$69),1),0) | F20: =COUNTIFS('3. Impacto_Melhor_Local'!$A$3:$A$69,$B20,'3. Impacto_Melhor_Local'!$I$3:$I$69,"Sim")/COUNTIF('3. Impacto_Melhor_Local'!$A$3:$A$69,$B20) | H20: ='2. Ranking_Candidatos'!C4&" ("&'2. Ranking_Candidatos'!B4&")" | I20: ='2. Ranking_Candidatos'!G4
B21: Aljezur | C21: =COUNTIF('3. Impacto_Melhor_Local'!$A$3:$A$69,$B21) | D21: =IFERROR(ROUND(SUMPRODUCT(('3. Impacto_Melhor_Local'!$A$3:$A$69=$B21)*'3. Impacto_Melhor_Local'!$C$3:$C$69*'3. Impacto_Melhor_Local'!$E$3:$E$69)/SUMPRODUCT(('3. Impacto_Melhor_Local'!$A$3:$A$69=$B21)*'3. Impacto_Melhor_Local'!$C$3:$C$69),1),0) | E21: =IFERROR(ROUND(SUMPRODUCT(('3. Impacto_Melhor_Local'!$A$3:$A$69=$B21)*'3. Impacto_Melhor_Local'!$C$3:$C$69*'3. Impacto_Melhor_Local'!$F$3:$F$69)/SUMPRODUCT(('3. Impacto_Melhor_Local'!$A$3:$A$69=$B21)*'3. Impacto_Melhor_Local'!$C$3:$C$69),1),0) | F21: =COUNTIFS('3. Impacto_Melhor_Local'!$A$3:$A$69,$B21,'3. Impacto_Melhor_Local'!$I$3:$I$69,"Sim")/COUNTIF('3. Impacto_Melhor_Local'!$A$3:$A$69,$B21) | H21: ='2. Ranking_Candidatos'!C5&" ("&'2. Ranking_Candidatos'!B5&")" | I21: ='2. Ranking_Candidatos'!G5
B22: Castro Marim | C22: =COUNTIF('3. Impacto_Melhor_Local'!$A$3:$A$69,$B22) | D22: =IFERROR(ROUND(SUMPRODUCT(('3. Impacto_Melhor_Local'!$A$3:$A$69=$B22)*'3. Impacto_Melhor_Local'!$C$3:$C$69*'3. Impacto_Melhor_Local'!$E$3:$E$69)/SUMPRODUCT(('3. Impacto_Melhor_Local'!$A$3:$A$69=$B22)*'3. Impacto_Melhor_Local'!$C$3:$C$69),1),0) | E22: =IFERROR(ROUND(SUMPRODUCT(('3. Impacto_Melhor_Local'!$A$3:$A$69=$B22)*'3. Impacto_Melhor_Local'!$C$3:$C$69*'3. Impacto_Melhor_Local'!$F$3:$F$69)/SUMPRODUCT(('3. Impacto_Melhor_Local'!$A$3:$A$69=$B22)*'3. Impacto_Melhor_Local'!$C$3:$C$69),1),0) | F22: =COUNTIFS('3. Impacto_Melhor_Local'!$A$3:$A$69,$B22,'3. Impacto_Melhor_Local'!$I$3:$I$69,"Sim")/COUNTIF('3. Impacto_Melhor_Local'!$A$3:$A$69,$B22) | H22: ='2. Ranking_Candidatos'!C6&" ("&'2. Ranking_Candidatos'!B6&")" | I22: ='2. Ranking_Candidatos'!G6
B23: Faro | C23: =COUNTIF('3. Impacto_Melhor_Local'!$A$3:$A$69,$B23) | D23: =IFERROR(ROUND(SUMPRODUCT(('3. Impacto_Melhor_Local'!$A$3:$A$69=$B23)*'3. Impacto_Melhor_Local'!$C$3:$C$69*'3. Impacto_Melhor_Local'!$E$3:$E$69)/SUMPRODUCT(('3. Impacto_Melhor_Local'!$A$3:$A$69=$B23)*'3. Impacto_Melhor_Local'!$C$3:$C$69),1),0) | E23: =IFERROR(ROUND(SUMPRODUCT(('3. Impacto_Melhor_Local'!$A$3:$A$69=$B23)*'3. Impacto_Melhor_Local'!$C$3:$C$69*'3. Impacto_Melhor_Local'!$F$3:$F$69)/SUMPRODUCT(('3. Impacto_Melhor_Local'!$A$3:$A$69=$B23)*'3. Impacto_Melhor_Local'!$C$3:$C$69),1),0) | F23: =COUNTIFS('3. Impacto_Melhor_Local'!$A$3:$A$69,$B23,'3. Impacto_Melhor_Local'!$I$3:$I$69,"Sim")/COUNTIF('3. Impacto_Melhor_Local'!$A$3:$A$69,$B23) | H23: ='2. Ranking_Candidatos'!C7&" ("&'2. Ranking_Candidatos'!B7&")" | I23: ='2. Ranking_Candidatos'!G7
B24: Lagoa | C24: =COUNTIF('3. Impacto_Melhor_Local'!$A$3:$A$69,$B24) | D24: =IFERROR(ROUND(SUMPRODUCT(('3. Impacto_Melhor_Local'!$A$3:$A$69=$B24)*'3. Impacto_Melhor_Local'!$C$3:$C$69*'3. Impacto_Melhor_Local'!$E$3:$E$69)/SUMPRODUCT(('3. Impacto_Melhor_Local'!$A$3:$A$69=$B24)*'3. Impacto_Melhor_Local'!$C$3:$C$69),1),0) | E24: =IFERROR(ROUND(SUMPRODUCT(('3. Impacto_Melhor_Local'!$A$3:$A$69=$B24)*'3. Impacto_Melhor_Local'!$C$3:$C$69*'3. Impacto_Melhor_Local'!$F$3:$F$69)/SUMPRODUCT(('3. Impacto_Melhor_Local'!$A$3:$A$69=$B24)*'3. Impacto_Melhor_Local'!$C$3:$C$69),1),0) | F24: =COUNTIFS('3. Impacto_Melhor_Local'!$A$3:$A$69,$B24,'3. Impacto_Melhor_Local'!$I$3:$I$69,"Sim")/COUNTIF('3. Impacto_Melhor_Local'!$A$3:$A$69,$B24) | H24: ='2. Ranking_Candidatos'!C8&" ("&'2. Ranking_Candidatos'!B8&")" | I24: ='2. Ranking_Candidatos'!G8
B25: Lagos | C25: =COUNTIF('3. Impacto_Melhor_Local'!$A$3:$A$69,$B25) | D25: =IFERROR(ROUND(SUMPRODUCT(('3. Impacto_Melhor_Local'!$A$3:$A$69=$B25)*'3. Impacto_Melhor_Local'!$C$3:$C$69*'3. Impacto_Melhor_Local'!$E$3:$E$69)/SUMPRODUCT(('3. Impacto_Melhor_Local'!$A$3:$A$69=$B25)*'3. Impacto_Melhor_Local'!$C$3:$C$69),1),0) | E25: =IFERROR(ROUND(SUMPRODUCT(('3. Impacto_Melhor_Local'!$A$3:$A$69=$B25)*'3. Impacto_Melhor_Local'!$C$3:$C$69*'3. Impacto_Melhor_Local'!$F$3:$F$69)/SUMPRODUCT(('3. Impacto_Melhor_Local'!$A$3:$A$69=$B25)*'3. Impacto_Melhor_Local'!$C$3:$C$69),1),0) | F25: =COUNTIFS('3. Impacto_Melhor_Local'!$A$3:$A$69,$B25,'3. Impacto_Melhor_Local'!$I$3:$I$69,"Sim")/COUNTIF('3. Impacto_Melhor_Local'!$A$3:$A$69,$B25) | H25: ='2. Ranking_Candidatos'!C9&" ("&'2. Ranking_Candidatos'!B9&")" | I25: ='2. Ranking_Candidatos'!G9
B26: Loulé | C26: =COUNTIF('3. Impacto_Melhor_Local'!$A$3:$A$69,$B26) | D26: =IFERROR(ROUND(SUMPRODUCT(('3. Impacto_Melhor_Local'!$A$3:$A$69=$B26)*'3. Impacto_Melhor_Local'!$C$3:$C$69*'3. Impacto_Melhor_Local'!$E$3:$E$69)/SUMPRODUCT(('3. Impacto_Melhor_Local'!$A$3:$A$69=$B26)*'3. Impacto_Melhor_Local'!$C$3:$C$69),1),0) | E26: =IFERROR(ROUND(SUMPRODUCT(('3. Impacto_Melhor_Local'!$A$3:$A$69=$B26)*'3. Impacto_Melhor_Local'!$C$3:$C$69*'3. Impacto_Melhor_Local'!$F$3:$F$69)/SUMPRODUCT(('3. Impacto_Melhor_Local'!$A$3:$A$69=$B26)*'3. Impacto_Melhor_Local'!$C$3:$C$69),1),0) | F26: =COUNTIFS('3. Impacto_Melhor_Local'!$A$3:$A$69,$B26,'3. Impacto_Melhor_Local'!$I$3:$I$69,"Sim")/COUNTIF('3. Impacto_Melhor_Local'!$A$3:$A$69,$B26) | H26: ='2. Ranking_Candidatos'!C10&" ("&'2. Ranking_Candidatos'!B10&")" | I26: ='2. Ranking_Candidatos'!G10
B27: Monchique | C27: =COUNTIF('3. Impacto_Melhor_Local'!$A$3:$A$69,$B27) | D27: =IFERROR(ROUND(SUMPRODUCT(('3. Impacto_Melhor_Local'!$A$3:$A$69=$B27)*'3. Impacto_Melhor_Local'!$C$3:$C$69*'3. Impacto_Melhor_Local'!$E$3:$E$69)/SUMPRODUCT(('3. Impacto_Melhor_Local'!$A$3:$A$69=$B27)*'3. Impacto_Melhor_Local'!$C$3:$C$69),1),0) | E27: =IFERROR(ROUND(SUMPRODUCT(('3. Impacto_Melhor_Local'!$A$3:$A$69=$B27)*'3. Impacto_Melhor_Local'!$C$3:$C$69*'3. Impacto_Melhor_Local'!$F$3:$F$69)/SUMPRODUCT(('3. Impacto_Melhor_Local'!$A$3:$A$69=$B27)*'3. Impacto_Melhor_Local'!$C$3:$C$69),1),0) | F27: =COUNTIFS('3. Impacto_Melhor_Local'!$A$3:$A$69,$B27,'3. Impacto_Melhor_Local'!$I$3:$I$69,"Sim")/COUNTIF('3. Impacto_Melhor_Local'!$A$3:$A$69,$B27) | H27: ='2. Ranking_Candidatos'!C11&" ("&'2. Ranking_Candidatos'!B11&")" | I27: ='2. Ranking_Candidatos'!G11
B28: Olhão | C28: =COUNTIF('3. Impacto_Melhor_Local'!$A$3:$A$69,$B28) | D28: =IFERROR(ROUND(SUMPRODUCT(('3. Impacto_Melhor_Local'!$A$3:$A$69=$B28)*'3. Impacto_Melhor_Local'!$C$3:$C$69*'3. Impacto_Melhor_Local'!$E$3:$E$69)/SUMPRODUCT(('3. Impacto_Melhor_Local'!$A$3:$A$69=$B28)*'3. Impacto_Melhor_Local'!$C$3:$C$69),1),0) | E28: =IFERROR(ROUND(SUMPRODUCT(('3. Impacto_Melhor_Local'!$A$3:$A$69=$B28)*'3. Impacto_Melhor_Local'!$C$3:$C$69*'3. Impacto_Melhor_Local'!$F$3:$F$69)/SUMPRODUCT(('3. Impacto_Melhor_Local'!$A$3:$A$69=$B28)*'3. Impacto_Melhor_Local'!$C$3:$C$69),1),0) | F28: =COUNTIFS('3. Impacto_Melhor_Local'!$A$3:$A$69,$B28,'3. Impacto_Melhor_Local'!$I$3:$I$69,"Sim")/COUNTIF('3. Impacto_Melhor_Local'!$A$3:$A$69,$B28) | H28: ='2. Ranking_Candidatos'!C12&" ("&'2. Ranking_Candidatos'!B12&")" | I28: ='2. Ranking_Candidatos'!G12
B29: Portimão | C29: =COUNTIF('3. Impacto_Melhor_Local'!$A$3:$A$69,$B29) | D29: =IFERROR(ROUND(SUMPRODUCT(('3. Impacto_Melhor_Local'!$A$3:$A$69=$B29)*'3. Impacto_Melhor_Local'!$C$3:$C$69*'3. Impacto_Melhor_Local'!$E$3:$E$69)/SUMPRODUCT(('3. Impacto_Melhor_Local'!$A$3:$A$69=$B29)*'3. Impacto_Melhor_Local'!$C$3:$C$69),1),0) | E29: =IFERROR(ROUND(SUMPRODUCT(('3. Impacto_Melhor_Local'!$A$3:$A$69=$B29)*'3. Impacto_Melhor_Local'!$C$3:$C$69*'3. Impacto_Melhor_Local'!$F$3:$F$69)/SUMPRODUCT(('3. Impacto_Melhor_Local'!$A$3:$A$69=$B29)*'3. Impacto_Melhor_Local'!$C$3:$C$69),1),0) | F29: =COUNTIFS('3. Impacto_Melhor_Local'!$A$3:$A$69,$B29,'3. Impacto_Melhor_Local'!$I$3:$I$69,"Sim")/COUNTIF('3. Impacto_Melhor_Local'!$A$3:$A$69,$B29)
B30: Silves | C30: =COUNTIF('3. Impacto_Melhor_Local'!$A$3:$A$69,$B30) | D30: =IFERROR(ROUND(SUMPRODUCT(('3. Impacto_Melhor_Local'!$A$3:$A$69=$B30)*'3. Impacto_Melhor_Local'!$C$3:$C$69*'3. Impacto_Melhor_Local'!$E$3:$E$69)/SUMPRODUCT(('3. Impacto_Melhor_Local'!$A$3:$A$69=$B30)*'3. Impacto_Melhor_Local'!$C$3:$C$69),1),0) | E30: =IFERROR(ROUND(SUMPRODUCT(('3. Impacto_Melhor_Local'!$A$3:$A$69=$B30)*'3. Impacto_Melhor_Local'!$C$3:$C$69*'3. Impacto_Melhor_Local'!$F$3:$F$69)/SUMPRODUCT(('3. Impacto_Melhor_Local'!$A$3:$A$69=$B30)*'3. Impacto_Melhor_Local'!$C$3:$C$69),1),0) | F30: =COUNTIFS('3. Impacto_Melhor_Local'!$A$3:$A$69,$B30,'3. Impacto_Melhor_Local'!$I$3:$I$69,"Sim")/COUNTIF('3. Impacto_Melhor_Local'!$A$3:$A$69,$B30)
B31: São Brás de Alportel | C31: =COUNTIF('3. Impacto_Melhor_Local'!$A$3:$A$69,$B31) | D31: =IFERROR(ROUND(SUMPRODUCT(('3. Impacto_Melhor_Local'!$A$3:$A$69=$B31)*'3. Impacto_Melhor_Local'!$C$3:$C$69*'3. Impacto_Melhor_Local'!$E$3:$E$69)/SUMPRODUCT(('3. Impacto_Melhor_Local'!$A$3:$A$69=$B31)*'3. Impacto_Melhor_Local'!$C$3:$C$69),1),0) | E31: =IFERROR(ROUND(SUMPRODUCT(('3. Impacto_Melhor_Local'!$A$3:$A$69=$B31)*'3. Impacto_Melhor_Local'!$C$3:$C$69*'3. Impacto_Melhor_Local'!$F$3:$F$69)/SUMPRODUCT(('3. Impacto_Melhor_Local'!$A$3:$A$69=$B31)*'3. Impacto_Melhor_Local'!$C$3:$C$69),1),0) | F31: =COUNTIFS('3. Impacto_Melhor_Local'!$A$3:$A$69,$B31,'3. Impacto_Melhor_Local'!$I$3:$I$69,"Sim")/COUNTIF('3. Impacto_Melhor_Local'!$A$3:$A$69,$B31)
B32: Tavira | C32: =COUNTIF('3. Impacto_Melhor_Local'!$A$3:$A$69,$B32) | D32: =IFERROR(ROUND(SUMPRODUCT(('3. Impacto_Melhor_Local'!$A$3:$A$69=$B32)*'3. Impacto_Melhor_Local'!$C$3:$C$69*'3. Impacto_Melhor_Local'!$E$3:$E$69)/SUMPRODUCT(('3. Impacto_Melhor_Local'!$A$3:$A$69=$B32)*'3. Impacto_Melhor_Local'!$C$3:$C$69),1),0) | E32: =IFERROR(ROUND(SUMPRODUCT(('3. Impacto_Melhor_Local'!$A$3:$A$69=$B32)*'3. Impacto_Melhor_Local'!$C$3:$C$69*'3. Impacto_Melhor_Local'!$F$3:$F$69)/SUMPRODUCT(('3. Impacto_Melhor_Local'!$A$3:$A$69=$B32)*'3. Impacto_Melhor_Local'!$C$3:$C$69),1),0) | F32: =COUNTIFS('3. Impacto_Melhor_Local'!$A$3:$A$69,$B32,'3. Impacto_Melhor_Local'!$I$3:$I$69,"Sim")/COUNTIF('3. Impacto_Melhor_Local'!$A$3:$A$69,$B32)
B33: Vila Real de Santo António | C33: =COUNTIF('3. Impacto_Melhor_Local'!$A$3:$A$69,$B33) | D33: =IFERROR(ROUND(SUMPRODUCT(('3. Impacto_Melhor_Local'!$A$3:$A$69=$B33)*'3. Impacto_Melhor_Local'!$C$3:$C$69*'3. Impacto_Melhor_Local'!$E$3:$E$69)/SUMPRODUCT(('3. Impacto_Melhor_Local'!$A$3:$A$69=$B33)*'3. Impacto_Melhor_Local'!$C$3:$C$69),1),0) | E33: =IFERROR(ROUND(SUMPRODUCT(('3. Impacto_Melhor_Local'!$A$3:$A$69=$B33)*'3. Impacto_Melhor_Local'!$C$3:$C$69*'3. Impacto_Melhor_Local'!$F$3:$F$69)/SUMPRODUCT(('3. Impacto_Melhor_Local'!$A$3:$A$69=$B33)*'3. Impacto_Melhor_Local'!$C$3:$C$69),1),0) | F33: =COUNTIFS('3. Impacto_Melhor_Local'!$A$3:$A$69,$B33,'3. Impacto_Melhor_Local'!$I$3:$I$69,"Sim")/COUNTIF('3. Impacto_Melhor_Local'!$A$3:$A$69,$B33)
B34: Vila do Bispo | C34: =COUNTIF('3. Impacto_Melhor_Local'!$A$3:$A$69,$B34) | D34: =IFERROR(ROUND(SUMPRODUCT(('3. Impacto_Melhor_Local'!$A$3:$A$69=$B34)*'3. Impacto_Melhor_Local'!$C$3:$C$69*'3. Impacto_Melhor_Local'!$E$3:$E$69)/SUMPRODUCT(('3. Impacto_Melhor_Local'!$A$3:$A$69=$B34)*'3. Impacto_Melhor_Local'!$C$3:$C$69),1),0) | E34: =IFERROR(ROUND(SUMPRODUCT(('3. Impacto_Melhor_Local'!$A$3:$A$69=$B34)*'3. Impacto_Melhor_Local'!$C$3:$C$69*'3. Impacto_Melhor_Local'!$F$3:$F$69)/SUMPRODUCT(('3. Impacto_Melhor_Local'!$A$3:$A$69=$B34)*'3. Impacto_Melhor_Local'!$C$3:$C$69),1),0) | F34: =COUNTIFS('3. Impacto_Melhor_Local'!$A$3:$A$69,$B34,'3. Impacto_Melhor_Local'!$I$3:$I$69,"Sim")/COUNTIF('3. Impacto_Melhor_Local'!$A$3:$A$69,$B34)
B37: 📈 GRÁFICO — Tempo médio de acesso por Concelho (Atual vs. C/ Novo Hospital)
B38: Freguesia | C38: Concelho | D38: Tempo Atual (min) | E38: Tempo C/ Novo Hosp. (min) | F38: Poupança (min)
B39: ='3. Impacto_Melhor_Local'!B3 | C39: ='3. Impacto_Melhor_Local'!A3 | D39: ='3. Impacto_Melhor_Local'!E3 | E39: ='3. Impacto_Melhor_Local'!F3 | F39: ='3. Impacto_Melhor_Local'!G3
B40: ='3. Impacto_Melhor_Local'!B4 | C40: ='3. Impacto_Melhor_Local'!A4 | D40: ='3. Impacto_Melhor_Local'!E4 | E40: ='3. Impacto_Melhor_Local'!F4 | F40: ='3. Impacto_Melhor_Local'!G4
B41: ='3. Impacto_Melhor_Local'!B5 | C41: ='3. Impacto_Melhor_Local'!A5 | D41: ='3. Impacto_Melhor_Local'!E5 | E41: ='3. Impacto_Melhor_Local'!F5 | F41: ='3. Impacto_Melhor_Local'!G5
B42: ='3. Impacto_Melhor_Local'!B6 | C42: ='3. Impacto_Melhor_Local'!A6 | D42: ='3. Impacto_Melhor_Local'!E6 | E42: ='3. Impacto_Melhor_Local'!F6 | F42: ='3. Impacto_Melhor_Local'!G6
...

Sheet 1. Resumo
B2: MODELO 2 — LOCALIZAÇÃO ÓTIMA DE NOVO HOSPITAL NO ALGARVE (COM CAPACIDADE)
B3: Ponderação por população: cada freguesia pesa Peso_i = População_i / População_total_Algarve. O modelo minimiza Σ Peso_i × Tempo_i (não a distância mínima 'no abstrato') — o critério já é 'onde estão as pessoas', não só a melhor localização geométrica. Ver detalhe por freguesia na folha '3. Impacto_Melhor_Local' (colunas Peso_Populacional_% e Tempo_Ponderado).
B5: Nº de freguesias no Algarve | C5: 67
B6: População total do Algarve | C6: 467343
B7: Camas necessárias totais na região | C7: 707.1
B9: ★ Melhor localização (Freguesia) | C9: Silves
B10: ★ Concelho | C10: Silves
B11: ★ Coordenadas (lat, lon) | C11: 37.1757, -8.4405
B13: Tempo médio ponderado ATUAL (só H. de Faro) | C13: 51.4
B14: Tempo médio ponderado COM novo hospital | C14: 37.7
B15: Redução de tempo médio (min) | C15: 13.7
B17: % freguesias críticas (>60min) ATUAL | C17: 50.7
B18: % freguesias críticas (>60min) COM novo hospital | C18: 25.4
B20: Freguesias que passam a usar o novo hospital | C20: 33
B21: População que passa a usar o novo hospital | C21: 217964
B22: % da população regional que muda | C22: 46.6
B24: Capacidade do Hospital de Faro (existente) | C24: 909.2
B25: Capacidade do novo hospital (assumida) | C25: 742
B26: Procura atribuída ao novo hospital | C26: 325.9
B27: Procura residual no Hospital de Faro | C27: 381.1
... B29: Défice de camas COM novo hospital | C29: 0
B31: Parâmetros do modelo
B32: Velocidade assumida (km/h) | C32: 60
B33: Tempo fixo de acesso (min) | C33: 15
B34: Nº de candidatos avaliados | C34: 67

Sheet 2. Ranking_Candidatos
A1: Ranking das 67 freguesias do Algarve como candidatas a novo hospital (742 camas) — menor custo = melhor
A2: Ranking | B2: Concelho | C2: Freguesia | D2: Populacao | E2: Lat_Freguesia | F2: Long_Freguesia | G2: tempo_medio_se_aqui | H2: defice_camas | I2: custo_ponderado
A3: 1 | B3: Silves | C3: Silves | D3: 10661 | E3: 37.175666 | F3: -8.4404647 | G3: 37.69 | H3: 0 | I3: 17614957
A4: 2 | B4: Lagoa | C4: Porches | D4: 2250 | E4: 37.125518 | F4: -8.3994888 | G4: 38.28 | H4: 0 | I4: 17889549
A5: 3 | B5: Lagos | C5: Odiáxere | D5: 3046 | E5: 37.149342 | F5: -8.6557705 | G5: 38.66 | H5: 0 | I5: 18065983
A6: 4 | B6: Portimão | C6: Portimão | D6: 49218 | E6: 37.180032 | F6: -8.5312516 | G6: 38.68 | H6: 0 | I6: 18076121
A7: 5 | B7: Portimão | C7: Mexilhoeira Grande | D7: 4313 | E7: 37.154179 | F7: -8.6096743 | G7: 38.76 | H7: 0 | I7: 18116163
A8: 6 | B8: Albufeira | C8: Guia | D8: 4758 | E8: 37.127028 | F8: -8.2996371 | G8: 38.93 | H8: 0 | I8: 18194237
A9: 7 | B9: Albufeira | C9: Ferreiras | D9: 7267 | E9: 37.127414 | F9: -8.243115 | G9: 39.06 | H9: 0 | I9: 18255205
A10: 8 | B10: Lagoa | C10: União das freguesias de Lagoa e Carvoeiro | D10: 10141 | E10: 37.117943 | F10: -8.4457434 | G10: 39.17 | H10: 0 | I10: 18305875
A11: 9 | B11: Silves | C11: União das freguesias de Alcantarilha e Pêra | D11: 4995 | E11: 37.146534 | F11: -8.3470002 | G11: 39.2 | H11: 0 | I11: 18319487
A12: 10 | B12: Silves | C12: Armação de Pêra | D12: 6003 | E12: 37.104238 | F12: -8.3627308 | G12: 39.39 | H12: 0 | I12: 18408635
A13: 11 | B13: Lagoa | C13: Ferragudo | D13: 1973 | E13: 37.123589 | F13: -8.5198921 | G13: 39.7 | H13: 0 | I13: 18554433
A14: 12 | B14: Lagoa | C14: União das freguesias de Estômbar e Parchal | D14: 9361 | E14: 37.139871 | F14: -8.4992942 | G14: 39.72 | H14: 0 | I14: 18564778
... A69: 67 | B69: Loulé | C69: Ameixial | D69: 381 | E69: 37.363364 | F69: -7.9632188 | G69: 51.18 | H69: 0 | I69: 23919915

Sheet 3. Impacto_Melhor_Local
A1: Impacto se o novo hospital (742 camas) ficar em: Silves (Silves) | Peso_Populacional = População_da_freguesia / População_total_Algarve | Tempo_Ponderado = Peso_Populacional × Tempo | Σ Tempo_Ponderado (todas as freguesias) = tempo médio ponderado por população (ver Resumo e bloco de verificação à direita).
A2: Concelho | B2: Freguesia | C2: Populacao | D2: Camas_Necessarias | E2: tempo_atual_min | F2: tempo_com_novo_hospital_min | G2: poupanca_min | H2: fracao_novo_hospital | I2: usa_novo_hospital | J2: Peso_Populacional_% | K2: Tempo_Ponderado_Atual | L2: Tempo_Ponderado_Novo | N2: Verificação — soma dos tempos ponderados (deve bater com a folha 1. Resumo)
A3: Silves | B3: Silves | C3: 10661 | D3: 16.9882 | E3: 60.9 | F3: 15 | G3: 45.9 | H3: 1 | I3: Sim | J3: 0.0228 | K3: 1.388 | L3: 0.342 | N3: Σ Peso_Populacional (deve ser 100%) | O3: =SUM(J3:J69)
A4: Lagoa | B4: União das freguesias de Lagoa e Carvoeiro | C4: 10141 | D4: 15.1994 | E4: 64.5 | F4: 27.9 | G4: 36.6 | H4: 1 | I4: Sim | J4: 0.0217 | K4: 1.4 | L4: 0.605 | N4: Σ Tempo_Ponderado_Atual = Tempo médio ATUAL | O4: =ROUND(SUM(K3:K69),1)
A5: Lagoa | B5: União das freguesias de Estômbar e Parchal | C5: 9361 | D5: 13.4406 | E5: 67 | F5: 31.1 | G5: 35.9 | H5: 1 | I5: Sim | J5: 0.02 | K5: 1.342 | L5: 0.623 | N5: Σ Tempo_Ponderado_Novo = Tempo médio COM novo hospital | O5: =ROUND(SUM(L3:L69),1)
A6: Lagoa | B6: Ferragudo | C6: 1973 | D6: 3.586 | E6: 69 | F6: 33.1 | G6: 35.9 | H6: 1 | I6: Sim | J6: 0.0042 | K6: 0.291 | L6: 0.14
A7: Portimão | B7: Alvor | C7: 6314 | D7: 9.7585 | E7: 72.5 | F7: 37 | G7: 35.5 | H7: 1 | I7: Sim | J7: 0.0135 | K7: 0.98 | L7: 0.5
A8: Vila do Bispo | B8: Budens | C8: 1857 | D8: 3.209 | E8: 89.8 | F8: 54.2 | G8: 35.5 | H8: 1 | I8: Sim | J8: 0.004 | K8: 0.357 | L8: 0.215
A9: Vila do Bispo | B9: Sagres | C9: 1894 | D9: 3.1946 | E9: 105.9 | F9: 70.4 | G9: 35.5 | H9: 1 | I9: Sim | J9: 0.0041 | K9: 0.429 | L9: 0.285
A10: Lagos | B10: Luz | C10: 4355 | D10: 7.5072 | E10: 83.5 | F10: 47.9 | G10: 35.5 | H10: 1 | I10: Sim | J10: 0.0093 | K10: 0.778 | L10: 0.447
A11: Aljezur | B11: Odeceixe | C11: 1055 | D11: 1.6346 | E11: 109.6 | F11: 74 | G11: 35.5 | H11: 1 | I11: Sim | J11: 0.0023 | K11: 0.247 | L11: 0.167
A12: Aljezur | B12: Aljezur | C12: 3455 | D12: 5.4224 | E12: 97.8 | F12: 62.3 | G12: 35.5 | H12: 1 | I12: Sim | J12: 0.0074 | K12: 0.723 | L12: 0.461
A13: Aljezur | B13: Bordeira | C13: 370 | D13: 0.6365 | E13: 96.7 | F13: 61.2 | G13: 35.5 | H13: 1 | I13: Sim | J13: 0.0008 | K13: 0.077 | L13: 0.048
A14: Lagos | B14: União das freguesias de Bensafrim e Barão de São João | C14: 2445 | D14: 4.0999 | E14: 75.6 | F14: 40.1 | G14: 35.5 | H14: 1 | I14: Sim | J14: 0.0052 | K14: 0.396 | L14: 0.21
A15: Lagos | B15: São Gonçalo de Lagos | C15: 23648 | D15: 35.3364 | E15: 76.9 | F15: 41.4 | G15: 35.5 | H15: 1 | I15: Sim | J15: 0.0506 | K15: 3.891 | L15: 2.093
A16: Lagos | B16: Odiáxere | C16: 3046 | D16: 4.5686 | E16: 71.3 | F16: 35.8 | G16: 35.5 | H16: 1 | I16: Sim | J16: 0.0065 | K16: 0.465 | L16: 0.233
A17: Portimão | B17: Portimão | C17: 49218 | D17: 71.0715 | E17: 72 | F17: 36.5 | G17: 35.5 | H17: 1 | I17: Sim | J17: 0.1053 | K17: 7.582 | L17: 3.839
... A69: Vila Real de Santo António | B69: Monte Gordo | C69: 3197 | D69: 4.9502 | E69: 59.9 | F69: 59.9 | G69: 0 | H69: 0 | I69: Não | J69: 0.0068 | K69: 0.41 | L69: 0.41
